Workbook

Sheet UNSKILLED
A2: HOME CARE/UNSKILLED Participant's First and Last Name | B2: Participant's ID | C2: Participant's Authorization Number | D2: BrightStar Employee | E2: Frequency | F2: No. of hours per visit | G2: Day(s) Scheduled | H2: Scheduled Service Time | I2: Date Approved | J2: Date Authorization Expires | K2: Remarks | L2: Home Care Contact | M2: Case Manager | N2: Contact No. (619) 515-2445 extension | O2: Email
A3: Adame, R. | B3: 100540727 | C3: 25359099 | D3: Bibiana M. | E3: 3xweek | F3: 2 | G3: Tues, Wed, Fri | H3: 12:00 am - 2:00 pm | I3: 45946 | J3: 46022 | K3: paused/on hold | L3: Gaunce, Christina <christinagau@fhcsd.org> | M3: Maribel | N3: 7017 | O3: maribele@fhcsd.org
A4: Adame-Hurtado, E. | B4: 100528529 | C4: 22810186 | D4: Adriana C. | E4: 3xweek | F4: 2 | G4: Tues, Wed, Fri | H4: 10:00 am - 12:00 am | I4: 45824 | J4: 45915 | K4: SNF | L4: Gaunce, Christina <christinagau@fhcsd.org> | M4: Maribel | N4: 7017 | O4: maribele@fhcsd.org
A5: Alcaraz, A. | B5: 101308633 | C5: 25131430 | D5: Trina H. | E5: 3xweek | F5: 2 | G5: M, W, F | H5: 9:00 am - 11:00 am | I5: 45994 | J5: 46081 | K5: - | L5: Bartolomei, Keri <kerib@fhcsd.org> | M5: Jocelyn | N5: (760) 826-7223 EXT 8072 | O5: jocelyng@fhcsd.org
A6: Alvarez, F. | B6: 100652558 | C6: 27102187 | D6: Perla C. | E6: 1x Week | F6: 2 | G6: Tues | H6: 1:00 pm - 3:00 pm | I6: 46029 | J6: 46082 | L6: Gaunce, Christina <christinagau@fhcsd.org> | M6: Aaron | N6: 7011 | O6: aarongo@fhcsd.org
A7: Alvarez, J. | B7: 100375790 | C7: 26835405 | D7: Perla C. | E7: 2x Week | F7: 2 | G7: Tues & Thurs | H7: 9:00 am - 11:00 am | I7: 46023 | J7: 46142 | L7: Gaunce, Christina <christinagau@fhcsd.org> | M7: Galia | N7: 3705 | O7: galias@fhcsd.org
A8: Anderman, C. | B8: 100677194 | C8: 25060838 | D8: Chelsea C. | E8: 1x Week | F8: 2 | G8: Wed | H8: 10:00am - 12:00pm | I8: 45933 | J8: 46081
A9: Arnold, M. | B9: 101304332 | C9: 26089949 | D9: Trina T. | E9: 5xweek | F9: 2 | G9: Mon to Fri | H9: 10:00am - 12:00pm | I9: 45980 | J9: 46081
A10: Arviso, J. | B10: 101294377 | C10: 24961917 | D10: Roya T. | E10: 2xweek | F10: 2 | G10: Wed, Fri | H10: 11:00 am - 1:00 pm | I10: 45929 | J10: 46104
A11: Bearden, K. | B11: 101358864 | C11: 23773688 | D11: Roya T. | E11: 1xweek | F11: 2 | G11: Mon | H11: 9:30AM - 11:30AM | I11: 45873 | J11: 46029 | K11: - | L11: Bartolomei, Keri <kerib@fhcsd.org> | M11: Jocelyn | N11: (760) 826-7223 EXT 8072 | O11: jocelyng@fhcsd.org
A12: Berend, S. | B12: 100836743 | C12: 22634863 | D12: Laura A. | E12: 4xweek | F12: 2 | G12: Wed, Thurs, Sat, Sun | H12: 12:00pm-2:00 pm | I12: 45925 | J12: 46081 | L12: Gaunce, Christina <christinagau@fhcsd.org> | M12: Danielle T. | N12: 3763 | O12: daniellet@fhcsd.org
A13: Bernanke, F. | B13: 101412699 | C13: 26947990 | D13: Tamir L. | E13: 2xweek | F13: 2 | G13: Tue, Thur | H13: 1:00 pm - 3:00 pm | I13: 46023 | J13: 46173 | L13: Gaunce, Christina <christinagau@fhcsd.org> | M13: Danielle T. | N13: 3763 | O13: daniellet@fhcsd.org
A14: Binder, J. | B14: 100754702 | C14: 25602406 | D14: Perla C. | E14: 5xweek | F14: 2 | G14: M, W, F, Sat and Sun | H14: 9am - 11am | I14: 45954 | J14: 46022 | K14: hospitalized/SNF | L14: Gaunce, Christina <christinagau@fhcsd.org> | M14: Lory | N14: 1707 | O14: Servil, Lory <lorys@fhcsd.org>
A15: Binder, J. | B15: 100754702 | C15: 25602406 | D15: Andres G. | E15: 2xweek | F15: 2 | G15: Tues,Thur | H15: 10am-12pm | I15: 45954 | J15: 46022 | L15: Gaunce, Christina <christinagau@fhcsd.org> | M15: Lory | N15: 1707 | O15: Servil, Lory <lorys@fhcsd.org>
A16: Bixby, R. | B16: 101391145 | C16: 26728263 | D16: Roya T. | E16: 1xweek | F16: 2 | G16: TBC | H16: 2:00pm - 4:00pm | I16: 45992 | J16: 46170
A17: Bolanos, A. | B17: 100875551 | C17: 24211905 | D17: Bethzaida K. | E17: 2xweek | F17: 2 | G17: Tue, Thur | H17: 2:00pm - 4:00pm | I17: 45890 | J17: 45688 | L17: Gaunce, Christina <christinagau@fhcsd.org>
A18: Boston, J. | B18: 101422408 | C18: 24329694 | D18: Chelsea C. | E18: 1xweek | F18: 2 | G18: Fri | H18: 10am-12pm | I18: 45898 | J18: 46056
A19: Bradbury, F. | B19: 100895931 | C19: 26668023 | D19: Aiden S. | E19: 7xweek | F19: 2 | G19: M-Fri | H19: 7am - 9am | I19: 46008 | J19: 46081 | L19: Gaunce, Christina <christinagau@fhcsd.org>
A20: Bradbury, F. | B20: 100895931 | C20: 26668023 | D20: Aiden S. | E20: 7xweek | F20: 2 | G20: Sat-sun | H20: 8am - 10am | I20: 46008 | J20: 46081 | L20: Gaunce, Christina <christinagau@fhcsd.org>
A21: Brae, A. | B21: 101306395 | C21: 26792309 | D21: Analhi C. | E21: 5xweek | F21: 2 | G21: Mon-Fri | H21: 11:00am-1:00 pm | I21: 46013 | J21: 46142 | L21: Gaunce, Christina <christinagau@fhcsd.org>
A22: Calderon, E. | B22: 100038800 | C22: 20793289 | D22: Margarita M. | E22: 3xWeek | F22: 2 | G22: Mon - Wed | H22: 8:00 am - 10:00 am | I22: 45915 | J22: 46053 | K22: Mon & Th: 8am & after 4pm visits | L22: Gaunce, Christina <christinagau@fhcsd.org> | M22: Mercy | N22: 5940 | O22: mercyc@fhcsd.org
A23: Calderon, E. | B23: 100038800 | C23: 20793289 | D23: Margarita M. | E23: 3xWeek | F23: 2 | G23: Mon - Wed | H23: 3:00 pm - 5:00 pm | I23: 45915 | J23: 46053 | K23: Mon & Th: 8am & after 4pm visits | L23: Gaunce, Christina <christinagau@fhcsd.org> | M23: Mercy | N23: 5940 | O23: mercyc@fhcsd.org
A24: Calderon, E. | B24: 100038800 | C24: 20793289 | D24: Perla C. | E24: 4xWeek | F24: 2 | G24: Thur - Sun | H24: 8:00 am - 10:00 am | I24: 45915 | J24: 46053 | K24: Mon & Th: 8am & after 4pm visits | L24: Gaunce, Christina <christinagau@fhcsd.org> | M24: Mercy | N24: 5940 | O24: mercyc@fhcsd.org
A25: Calderon, E. | B25: 100038800 | C25: 20793289 | D25: Perla C. | E25: 4xWeek | F25: 2 | G25: Thur - Sun | H25: 3:00 pm - 5:00 pm | I25: 45915 | J25: 46053 | K25: Mon & Th: 8am & after 4pm visits | L25: Gaunce, Christina <christinagau@fhcsd.org> | M25: Mercy | N25: 5940 | O25: mercyc@fhcsd.org
A26: Campbell, C. | B26: 101375560 | C26: 26792866 | D26: Aiden S. | E26: 7xwek | F26: 2 | G26: Daily | H26: 3:00 pm - 5:00 pm | I26: 46029 | J26: 46054 | L26: Gaunce, Christina <christinagau@fhcsd.org> | M26: Lory | N26: 1707 | O26: Servil, Lory <lorys@fhcsd.org>
A27: Chaaban, R. | B27: 101289778 | C27: 25987335 | D27: Analhi C. | E27: 1xweek | F27: 2 | G27: Tues | H27: 11:00am-1:00 pm | I27: 46023 | J27: 46142 | M27: Shari | N27: (760) 826-7223 EXT 8073 | O27: ; sharid@fhcsd.org
A28: Contreras-Padilla, S. | B28: 101360806 | C28: 18749853 | D28: Trina T. | I28: 45580 | J28: 45747 | K28: Escort assistance only | L28: Bartolomei, Keri <kerib@fhcsd.org> | M28: Shari | N28: (760) 826-7223 EXT 8073 | O28: ; sharid@fhcsd.org
A29: Cork, J. | B29: 101403930 | C29: 25060742 | D29: Analhi C. | E29: 2xweek | F29: 2 | G29: Friday | H29: 8:00 am - 10:00 am | I29: 45933 | J29: 46081 | K29: - | L29: Bartolomei, Keri <kerib@fhcsd.org> | M29: Shari | N29: (760) 826-7223 EXT 8073 | O29: ; sharid@fhcsd.org
A30: Corrales, G. | B30: 100151102 | C30: 22928116 | D30: Adriana C. | E30: 2xweek | F30: 2 | G30: Tues & Thurs | H30: 12:00pm-2:00 pm | I30: 45832 | J30: 46014 | L30: Gaunce, Christina <christinagau@fhcsd.org> | M30: Aaron | N30: 7011 | O30: aarongo@fhcsd.org
A31: Cory, L. | B31: 100798512 | C31: 25854959 | D31: Bibiana M. | E31: 3xweek | F31: 2 | G31: Mon, Thurs, Sat | H31: 1:30pm - 3:30pm | I31: 45968 | J31: 46173 | L31: Gaunce, Christina <christinagau@fhcsd.org> | M31: Aaron | N31: 7011 | O31: aarongo@fhcsd.org
A32: Cross, W. | B32: 100367273 | C32: 23924378 | D32: Khadijah M. | E32: 1xWeek | F32: 4 | G32: Thurs | H32: 9:00 am - 1:00 pm | I32: 45854 | J32: 46037 | L32: Gaunce, Christina <christinagau@fhcsd.org> | M32: Danielle T. | N32: 3763 | O32: daniellet@fhcsd.org
A33: Diaz, M. F. | B33: 100829155 | C33: 26703685 | D33: Susan R. | E33: 5xweek | F33: 2 | G33: Mon - Fri | H33: 9:00am - 11:00 am | I33: 46008 | J33: 46022 | K33: pending updated auth | L33: Gaunce, Christina <christinagau@fhcsd.org>
A34: Diaz, M. F. | B34: 100829155 | C34: 26703685 | D34: Khadijah M. | E34: 5xweek | F34: 2 | G34: Mon - Fri | H34: 9:00am - 11:00 am | I34: 45939 | J34: 46022 | K34: pending updated auth | L34: Gaunce, Christina <christinagau@fhcsd.org>
A35: Dulina, D. | B35: 100796423 | C35: 23535030 | D35: Felicia A. | E35: 2xweek | F35: 2 | G35: Tue,Thur | H35: 3:00pm - 5:00pm | I35: 45919 | J35: 46081 | L35: Gaunce, Christina <christinagau@fhcsd.org> | M35: Nehita | N35: 7012 | O35: nehitao@fhcsd.org
A36: Figueroa Garcia, R. | B36: 100694449 | C36: 23967101 | D36: Diana M. | E36: 3xweek | F36: 4 | G36: Tues, Thurs | H36: 8:00 am - 12:00 pm | I36: 45887 | J36: 46053 | L36: Gaunce, Christina <christinagau@fhcsd.org> | M36: Aaron | N36: 7011 | O36: aarongo@fhcsd.org
A37: Figueroa Garcia, R. | B37: 100694449 | C37: 23967101 | D37: Perla C. | E37: 1xweek | F37: 4 | G37: Sat | H37: 8:00 am - 12:00 pm | I37: 45887 | J37: 46053 | L37: Gaunce, Christina <christinagau@fhcsd.org> | M37: Aaron | N37: 7011 | O37: aarongo@fhcsd.org
A38: Flenoid, C. | B38: 100113365 | C38: 26916545 | D38: Susan R. | E38: 1xweek | F38: 2 | G38: Tuesday | H38: 7am - 9am | I38: 46027 | J38: 46203 | L38: Mercy | M38: 5940 | N38: mercyc@fhcsd.org
A39: Flenoid, C. | B39: 100113365 | C39: 26916545 | D39: Susan R. | E39: 6xweek | F39: 2 | G39: M, W,Th,F,Sat,Sun | H39: 8am - 10am | I39: 46027 | J39: 46203
A40: Flenoid, C. | B40: 100113365 | C40: 26916545 | D40: TBD | E40: 3xweek | F40: 2 | G40: W,Th | H40: 1pm-3pm | I40: 46027 | J40: 46203 | L40: Mercy | M40: 5940 | N40: mercyc@fhcsd.org
A41: Flores, E. | B41: 101314884 | C41: 26242512 | D41: Analhi C. | E41: 1xweek | F41: 2 | G41: Wed | H41: 10am - 12pm | I41: 45986 | J41: 46173
...

Sheet SKILLED
A1: HOME HEALTH/SKILLED Participant's First and Last Name | B1: Participant's ID | C1: Participant's Authorization Number | D1: BrightStar Employee | E1: Frequency | F1: No. of hours per visit | G1: Day(s) Scheduled | H1: Scheduled Service Time | I1: Date Approved | J1: Date Authorization Expires | K1: REMARKS | L1: Case Managers | M1: Contact No. (619) 515-2445) extension | N1: Email
A2: Adame, R. | B2: 100528529 | C2: 26403468 | D2: Margo P. | E2: 1xweek | F2: 2 | G2: Wed | H2: 10:00 am - 12:00 pm | I2: 45995 | J2: 46177 | L2: Maribel | M2: 7017 | N2: maribele@fhcsd.org
A3: Adame-Hurtado, E. | B3: 100528529 | C3: 24532154 | D3: Margo P. | E3: 7xweek | F3: 2 | G3: Mon-Sun | H3: 10:00 am - 12:00 am | I3: 45909 | J3: 46000 | K3: hospitalized / SNF | L3: Maribel | M3: 7017 | N3: maribele@fhcsd.org
A4: Alcaraz, A. | B4: 101308633 | C4: 27125033 | D4: Anders | E4: 2xweek | F4: 2 | G4: Tue-Thurs | H4: 9:00 am - 11:00 am | I4: 46031 | J4: 46062 | K4: - | L4: Jocelyn | M4: (760) 826-7223 EXT 8072 | N4: jocelyng@fhcsd.org
A5: Appell, L. | B5: 101157222 | C5: 25992939 | D5: Rochelle G. | E5: 1xweek | F5: 2 | G5: Mon | H5: 10:00 am - 12:00 pm | I5: 46005 | J5: 46095 | L5: Danielle T. | M5: 3763 | N5: daniellet@fhcsd.org
A6: Araujo, D. | B6: 100024820 | C6: 25983481 | D6: Malcolm L. | E6: 2xweek | F6: 2 | G6: Mon & Fri | H6: 8am-10am | I6: 45974 | J6: 46060 | K6: cancelled | L6: Maribel | M6: 7017 | N6: maribele@fhcsd.org
A7: Baker, R. | B7: 101164531 | C7: 22215887 | D7: Rochelle G. | E7: 4xweek | F7: 2 | G7: Tue, Wed, Thurs, Fri | H7: 9:30am - 11:30am | I7: 45793 | J7: 45918 | K7: hospitalized / SNF
A8: Barajas Barragan, A. | B8: 100130870 | C8: 26730686 | D8: Malcolm L. | E8: 1xweek | F8: 2 | G8: Wed | H8: 3p-5p | I8: 46009 | J8: 46189 | L8: Maribel | M8: 7017 | N8: maribele@fhcsd.org
A9: Bernanke, F. | B9: 101412699 | C9: 26712758 | D9: Gabriela M. | E9: 3xweek | F9: 2 | G9: M, T, Th | H9: 1pm-3pm | I9: 46009 | J9: 46127 | L9: Lory | M9: 1707 | N9: Servil, Lory <lorys@fhcsd.org>
A10: Bernanke, F. | B10: 101412699 | C10: 26712758 | D10: Colleen R. | E10: 1xweek | F10: 2 | G10: Fri | H10: 1pm-3pm | I10: 46009 | J10: 46127 | L10: Lory | M10: 1707 | N10: Servil, Lory <lorys@fhcsd.org>
A11: Bernanke, F. | B11: 101412699 | C11: 26712758 | D11: Eric E. | E11: 1xweek | F11: 2 | G11: Sat | H11: 1pm-3pm | I11: 46009 | J11: 46127 | L11: Lory | M11: 1707 | N11: Servil, Lory <lorys@fhcsd.org>
A12: Binder, J. | B12: 100754702 | C12: 25213847 | D12: Malcolm L. | E12: 2xweek | F12: 2 | G12: Tue, Thur | H12: 11:30am - 1:00pm | I12: 45940 | J12: 46112 | K12: hospitalized/SNF | L12: Lory | M12: 1707 | N12: Servil, Lory <lorys@fhcsd.org>
A13: Binder, J. | B13: 100754702 | C13: 25213847 | D13: Rochelle G. | E13: 5xweek | F13: 2 | G13: M,W,F,Sat and Sun | H13: 11:30am - 1:00pm | I13: 45940 | J13: 46112 | K13: hospitalized/SNF | L13: Lory | M13: 1707 | N13: Servil, Lory <lorys@fhcsd.org>
A14: Brae, A. | B14: 101306395 | C14: 25758128 | D14: Malcolm L. | E14: 3xweek | F14: 2 | G14: Wed, Fri, Sat, | H14: 9:30a-11:30a | I14: 45966 | J14: 46147 | L14: Lory | M14: 1707 | N14: Servil, Lory <lorys@fhcsd.org>
A15: Brae, A. | B15: 101306395 | C15: 25758128 | D15: Felsie C. | E15: 1xweek | F15: 2 | G15: Sun | H15: 9:30a-11:30a | I15: 45966 | J15: 46147 | L15: Lory | M15: 1707 | N15: Servil, Lory <lorys@fhcsd.org>
A16: Calderon, E. | B16: 100038800 | C16: 26473904 | D16: Mary B. | E16: 5xweek | F16: 2 | G16: Mon-Fri | H16: 7am-9am | I16: 45996 | J16: 46185 | L16: Mercy | M16: 5940 | N16: mercyc@fhcsd.org
A17: Calderon, E. | B17: 100038800 | C17: 26473904 | D17: Amanda M. | E17: 2xweek | F17: 2 | G17: Sat & Sun | H17: 7am-9am | I17: 45996 | J17: 46185 | L17: Mercy | M17: 5940 | N17: mercyc@fhcsd.org
A18: Calderon, G. | B18: 100512664 | C18: 23232183 | D18: Malcolm L. | E18: 1xweek | F18: 2 | G18: Tue | H18: 5pm-7pm | I18: 45847 | J18: 46030 | K18: 5pm preferred | L18: Aaron | M18: 7011 | N18: aarongo@fhcsd.org
A19: Camarda, T. | B19: 101323503 | C19: 26242044 | E19: 1xweek | F19: 2 | G19: TBC | H19: TBC | I19: 45986 | J19: 46022 | L19: Maribel | M19: 7017 | N19: maribele@fhcsd.org
A20: Campbell, C. | B20: 101375560 | C20: 26816416 | D20: Ejigayehu W. | E20: 2xweek | F20: 2 | G20: Tue & Fri | H20: 1pm-3pm | I20: 46017 | J20: 46157 | L20: Aaron | M20: 7011 | N20: aarongo@fhcsd.org
A21: Chaaban, R. | B21: 101289778 | C21: 25569214 | D21: Joshua H. | E21: 1xweek | F21: 2 | G21: Thurs | H21: 6pm-8pm | I21: 46023 | J21: 46073 | L21: Shari | M21: (760) 826-7223 EXT 8073 | N21: ; sharid@fhcsd.org
A22: Contreras, B. | B22: 100754584 | C22: 27177689 | D22: Cynthia R. | E22: 1xweek | F22: 2 | G22: Tues | H22: 10am - 12pm | I22: 46031 | J22: 46128
A23: Corrales, G. | B23: 100151102 | C23: 23231830 | D23: Lensa J. | E23: 1xweek | F23: 2 | G23: Wed | H23: 6pm-8pm | I23: 45847 | J23: 46030 | L23: Aaron | M23: 7011 | N23: aarongo@fhcsd.org
A24: Cory, L. | B24: 100798512 | C24: 26986703 | D24: Jijee W. | E24: 2xweek | F24: 2 | G24: Mon & Wed | H24: 1pm-3pm | I24: 46024 | J24: 46143 | L24: Aaron | M24: 7011 | N24: aarongo@fhcsd.org
A25: Cory, L. | B25: 100798512 | C25: 26986703 | D25: Monique R. | E25: 1xweek | F25: 2 | G25: Friday | H25: 1pm-3pm | I25: 46024 | J25: 46143 | L25: Aaron | M25: 7011 | N25: aarongo@fhcsd.org
A26: Cross, W. | B26: 100367273 | C26: 23266481 | D26: Eric E. | E26: 1xWeek | F26: 2 | G26: Tue | H26: 11a-1p | I26: 45854 | J26: 46037 | L26: Danielle T. | M26: 3763 | N26: daniellet@fhcsd.org
A27: De Leon, M. | B27: 100096800 | C27: 27095850 | D27: Akilah H. | E27: 5xweek | F27: 2 | G27: Mon-Fri | H27: 9am-11am | I27: 46029 | J27: 46119 | L27: Mercy | M27: 5940 | N27: mercyc@fhcsd.org
A28: Del Rio, R. | B28: 101236755 | C28: 21485764 | D28: Fatemeh V. | E28: 4xweek | F28: 2 | G28: Mon, Tue, Thu, Fri | H28: 9am-11am | I28: 45758 | J28: 45848 | K28: on hold as of 6/9 | L28: Mercy | M28: 5940 | N28: mercyc@fhcsd.org
A29: Del Rio, R. | B29: 101236755 | C29: 21485764 | D29: Amanda M. | E29: 2xweek | F29: 2 | G29: Sat & Sun | H29: 9am-11am | I29: 45758 | J29: 45848 | K29: on hold as of 6/9 | L29: Mercy | M29: 5940 | N29: mercyc@fhcsd.org
A30: Del Rio, R. | B30: 101236755 | C30: 21485764 | D30: Priscilla C. | E30: 2xweek | F30: 2 | G30: Wed | H30: 9am-11am | I30: 45758 | J30: 45848 | K30: on hold as of 6/9 | L30: Mercy | M30: 5940 | N30: mercyc@fhcsd.org
A31: Del Rio, R. | B31: 101236755 | C31: 21485764 | D31: Ejigayehu W. | E31: 5xweek | F31: 2 | G31: Mon - Fri | H31: 3pm-5pm | I31: 45758 | J31: 45848 | K31: on hold as of 6/9 | L31: Mercy | M31: 5940 | N31: mercyc@fhcsd.org
A32: Del Rio, R. | B32: 101236755 | C32: 21485764 | D32: Nadhii B. | E32: 2xweek | F32: 2 | G32: Sat & Sun | H32: 3pm-5pm | I32: 45758 | J32: 45848 | K32: on hold as of 6/9 | L32: Mercy | M32: 5940 | N32: mercyc@fhcsd.org
A33: Diaz, M. F. | B33: 100829155 | C33: 26898928 | D33: Malcolm L. | E33: 1xweek | F33: 2 | H33: 12pm-2pm | I33: 46020 | J33: 46201
A34: Doan, M. | B34: 101051619 | C34: 26016803 | D34: Noel L. | E34: 2xweek | F34: 2 | G34: Tue, Thur | H34: 9am-11am | I34: 45975 | J34: 46156 | L34: Aaron | M34: 7011 | N34: aarongo@fhcsd.org
A35: Dulina, D. | B35: 100796423 | C35: 27177428 | D35: Gabriela M. | E35: 2xweek | F35: 2 | G35: Tues & Sat | H35: 4pm-6pm | I35: 46031 | J35: 07/11/226 | K35: Sat, Sun, holidays | L35: Lory | M35: 1707 | N35: Servil, Lory <lorys@fhcsd.org>
A36: Figueroa Garcia, R. | B36: 100894449 | C36: 26563639 | D36: Renee R. | E36: 5xWeek | F36: 2 | G36: Mon-Fri | H36: 12pm-2pm | I36: 46002 | J36: 46184 | L36: Maribel | M36: 7017 | N36: maribele@fhcsd.org
A37: Figueroa Garcia, R. | B37: 100894449 | C37: 26563639 | D37: Kathleen B. | E37: 1xWeek | F37: 2 | G37: Sat & Sun | H37: 12pm-2pm | I37: 46002 | J37: 46184 | L37: Maribel | M37: 7017 | N37: maribele@fhcsd.org
A38: Flenoid, C. | B38: 10011365 | C38: 23684203 | D38: Kathleen B. | E38: 5xweek | F38: 2 | G38: MWTFS | H38: 1pm-3pm | I38: 45867 | J38: 46050 | L38: Mercy | M38: 5940 | N38: mercyc@fhcsd.org
A39: Franco, M. | B39: 100135432 | C39: 26793630 | D39: Cynthia R. | E39: 3xweek | F39: 2 | G39: M, W,F | H39: 11a-1p | I39: 46006 | J39: 46192 | L39: Aaron | M39: 7011 | N39: aarongo@fhcsd.org
A40: Fudge, R. | B40: 101096605 | C40: 26380416 | D40: Nicole S. | E40: 5xweek | F40: 2 | G40: Mon-Fri | H40: 11a-1p | I40: 45994 | J40: 46083
...

Sheet Discharged PPT
D4: Participant's First and Last Name | E4: Discharged Date
D5: Calvin Milner | E5: 44745
D6: Karen Lee Patton | E6: 44754
D7: Philip Bishay | E7: 44754
D8: Della Clark | E8: 44774
D9: Sammie Neve | E9: 44785
D10: Redolfo Casil | E10: 44798
D11: Delareco Pacely | E11: 44790
D12: Guillermo Corrales | E12: 44903
D13: Mario Mendez | E13: 44889
D14: Maria Santa Lopez | E14: 44897
D15: Zoila Coto Rodriguez | E15: 44924
D16: Rochelle Olsen | E16: 44911
... D20: Richard Johnson | E20: 44943
D21: Rogelio Gomez
D22: Natalie Balard | E22: 44952
D23: Flores Cota, M. | E23: 44964
D24: Guerrero, R. | E24: 44977
D25: Mason, P. | E25: 44980
D26: Verduzco Mota, E. | E26: 44982
D27: Kirkland, J. | E27: 44996
D28: Bergelin, R. | E28: 45015
D29: Estrada, I. | E29: 45000
D30: Woodward, D. | E30: 45003
D31: Flores, T. | E31: 45009
D32: Cory, L. | E32: 45015
D33: Diaz, M. | E33: 45016
... D45: Wallace, D. | E45: 45099
D46: Delrio, R. | E46: 45136 | F46: Hospitalized/SNF
D47: Thamarath, O. | E47: 45110
D48: Jackson, K. | E48: 45120
D49: Sepich, M. | E49: 45131
D50: De Nolf, T. | E50: 45132
D51: Cooper, S. | E51: 45137
D52: Mora, A. | E52: 45161
D53: Nemetz, R. | E53: 45161
D54: Clark, D. | E54: 45162 | F54: Cancelled 8/24 per Gwen's email
D55: Szczygiel, T. | E55: 45164
D56: Govan, A. | E56: 45166
D57: Maciel, I. | E57: 45180
...

Sheet EXPIRATION DATES
A1: HOME HEALTH/SKILLED Participant's Name | B1: Date Approved | C1: Date Authorization Expires | D1: REMARKS | I1: HOME CARE/UNSKILLED Participant's Name | J1: Date Approved | K1: Date Authorization Expires | L1: REMARKS
A2: Garcia Ramirez, R. | B2: =VLOOKUP(A2,SKILLED!A:I,9,0) -> 45744 | C2: =VLOOKUP(A2,SKILLED!$A:$J,10,0) -> 45808 | D2: SNF | I2: Adame-Hurtado, E. | J2: =VLOOKUP(I2,UNSKILLED!$A:$J,9,0) -> 45824 | K2: =VLOOKUP(I2,UNSKILLED!$A:$J,10,0) -> 45915 | L2: hospitalized/SNF
A3: Willis, J. | B3: =VLOOKUP(A3,SKILLED!A:I,9,0) -> 45667 | C3: =VLOOKUP(A3,SKILLED!$A:$J,10,0) -> 45848 | D3: Hospitalized 2/14/25 per RNCM Nehita | I3: Turest, V. | J3: =VLOOKUP(I3,UNSKILLED!$A:$J,9,0) -> 45789 | K3: =VLOOKUP(I3,UNSKILLED!$A:$J,10,0) -> 45973 | L3: hospitalized/SNF
A4: Baker, R. | B4: =VLOOKUP(A4,SKILLED!A:I,9,0) -> 45793 | C4: =VLOOKUP(A4,SKILLED!$A:$J,10,0) -> 45918 | D4: SNF | I4: Newport, L. | J4: =VLOOKUP(I4,UNSKILLED!$A:$J,9,0) -> 46008 | K4: =VLOOKUP(I4,UNSKILLED!$A:$J,10,0) -> 46013 | L4: 1x visit only
A5: Zuniga Sandoval, V. | B5: =VLOOKUP(A5,SKILLED!A:I,9,0) -> 45854 | C5: =VLOOKUP(A5,SKILLED!$A:$J,10,0) -> 45945 | D5: expired | I5: Turcios, S. | J5: =VLOOKUP(I5,UNSKILLED!$A:$J,9,0) -> 45836 | K5: =VLOOKUP(I5,UNSKILLED!$A:$J,10,0) -> 46022 | L5: extended, pending updated auth Weekends
A6: Taylor, H. | B6: =VLOOKUP(A6,SKILLED!A:I,9,0) -> 45911 | C6: =VLOOKUP(A6,SKILLED!$A:$J,10,0) -> 45947 | D6: waiting for auth from 10/17 - 11/5 | I6: Diaz, M. F. | J6: =VLOOKUP(I6,UNSKILLED!$A:$J,9,0) -> 46008 | K6: =VLOOKUP(I6,UNSKILLED!$A:$J,10,0) -> 46022 | L6: extended, pending updated auth with corrected expiration date
A7: Turest, V. | B7: =VLOOKUP(A7,SKILLED!A:I,9,0) -> 45789 | C7: =VLOOKUP(A7,SKILLED!$A:$J,10,0) -> 45973 | D7: SNF | I7: Adame, R. | J7: =VLOOKUP(I7,UNSKILLED!$A:$J,9,0) -> 45946 | K7: =VLOOKUP(I7,UNSKILLED!$A:$J,10,0) -> 46022 | L7: paused/on hold
A8: Adame-Hurtado, E. | B8: =VLOOKUP(A8,SKILLED!A:I,9,0) -> 45909 | C8: =VLOOKUP(A8,SKILLED!$A:$J,10,0) -> 46000 | D8: SNF | I8: Binder, J. | J8: =VLOOKUP(I8,UNSKILLED!$A:$J,9,0) -> 45954 | K8: =VLOOKUP(I8,UNSKILLED!$A:$J,10,0) -> 46022 | L8: pending DC date/plan from SNF
A9: Camarda, T. | B9: =VLOOKUP(A9,SKILLED!A:I,9,0) -> 45986 | C9: =VLOOKUP(A9,SKILLED!$A:$J,10,0) -> 46022 | D9: Expired | I9: McGinn, M. | J9: =VLOOKUP(I9,UNSKILLED!$A:$J,9,0) -> 45972 | K9: =VLOOKUP(I9,UNSKILLED!$A:$J,10,0) -> 46022 | L9: hospitalized/SNF
A10: Gonzalez, L. | B10: =VLOOKUP(A10,SKILLED!A:I,9,0) -> 45957 | C10: =VLOOKUP(A10,SKILLED!$A:$J,10,0) -> 46023 | D10: Expired | I10: Bearden, K. | J10: =VLOOKUP(I10,UNSKILLED!$A:$J,9,0) -> 45873 | K10: =VLOOKUP(I10,UNSKILLED!$A:$J,10,0) -> 46029 | L10: EXPIRED
A11: Mclaughlin, J. | B11: =VLOOKUP(A11,SKILLED!A:I,9,0) -> 45957 | C11: =VLOOKUP(A11,SKILLED!$A:$J,10,0) -> 46023 | D11: extended, auth is missing the exp date | I11: Cross, W. | J11: =VLOOKUP(I11,UNSKILLED!$A:$J,9,0) -> 45854 | K11: =VLOOKUP(I11,UNSKILLED!$A:$J,10,0) -> 46037
A12: Corrales, G. | B12: =VLOOKUP(A12,SKILLED!A:I,9,0) -> 45847 | C12: =VLOOKUP(A12,SKILLED!$A:$J,10,0) -> 46030 | D12: Expired | I12: Green, R. | J12: =VLOOKUP(I12,UNSKILLED!$A:$J,9,0) -> 45855 | K12: =VLOOKUP(I12,UNSKILLED!$A:$J,10,0) -> 46038
A13: Calderon, G. | B13: =VLOOKUP(A13,SKILLED!A:I,9,0) -> 45847 | C13: =VLOOKUP(A13,SKILLED!$A:$J,10,0) -> 46030 | D13: Expired | I13: Joy, J. | J13: =VLOOKUP(I13,UNSKILLED!$A:$J,9,0) -> 45870 | K13: =VLOOKUP(I13,UNSKILLED!$A:$J,10,0) -> 46053
A14: Verduzco, E. | B14: =VLOOKUP(A14,SKILLED!A:I,9,0) -> 11/22/205 | C14: =VLOOKUP(A14,SKILLED!$A:$J,10,0) -> 46033 | D14: extended waiting for auth | I14: Snyder, C. | J14: =VLOOKUP(I14,UNSKILLED!$A:$J,9,0) -> 46002 | K14: =VLOOKUP(I14,UNSKILLED!$A:$J,10,0) -> 46053
A15: Kirkland, J. | B15: =VLOOKUP(A15,SKILLED!A:I,9,0) -> 45853 | C15: =VLOOKUP(A15,SKILLED!$A:$J,10,0) -> 46036 | D15: Hospitalized | I15: Figueroa Garcia, R. | J15: =VLOOKUP(I15,UNSKILLED!$A:$J,9,0) -> 45887 | K15: =VLOOKUP(I15,UNSKILLED!$A:$J,10,0) -> 46053
A16: Cross, W. | B16: =VLOOKUP(A16,SKILLED!A:I,9,0) -> 45854 | C16: =VLOOKUP(A16,SKILLED!$A:$J,10,0) -> 46037 | I16: Mendez, M. | J16: =VLOOKUP(I16,UNSKILLED!$A:$J,9,0) -> 45888 | K16: =VLOOKUP(I16,UNSKILLED!$A:$J,10,0) -> 46053
A17: Flenoid, C. | B17: =VLOOKUP(A17,SKILLED!A:I,9,0) -> 45867 | C17: =VLOOKUP(A17,SKILLED!$A:$J,10,0) -> 46050 | I17: Smith, C. | J17: =VLOOKUP(I17,UNSKILLED!$A:$J,9,0) -> 45891 | K17: =VLOOKUP(I17,UNSKILLED!$A:$J,10,0) -> 46053
A18: Gardner, N. | B18: =VLOOKUP(A18,SKILLED!A:I,9,0) -> 45867 | C18: =VLOOKUP(A18,SKILLED!$A:$J,10,0) -> 46050 | I18: Calderon, E. | J18: =VLOOKUP(I18,UNSKILLED!$A:$J,9,0) -> 45915 | K18: =VLOOKUP(I18,UNSKILLED!$A:$J,10,0) -> 46053
A19: Herrera, G. | B19: =VLOOKUP(A19,SKILLED!A:I,9,0) -> 45867 | C19: =VLOOKUP(A19,SKILLED!$A:$J,10,0) -> 46050 | I19: Mcdonald, G. | J19: =VLOOKUP(I19,UNSKILLED!$A:$J,9,0) -> 45931 | K19: =VLOOKUP(I19,UNSKILLED!$A:$J,10,0) -> 46053
A20: Vega, S. | B20: =VLOOKUP(A20,SKILLED!A:I,9,0) -> 45839 | C20: =VLOOKUP(A20,SKILLED!$A:$J,10,0) -> 46053 | I20: Holmes, E. | J20: =VLOOKUP(I20,UNSKILLED!$A:$J,9,0) -> 45936 | K20: =VLOOKUP(I20,UNSKILLED!$A:$J,10,0) -> 46053
A21: Araujo, D. | B21: =VLOOKUP(A21,SKILLED!A:I,9,0) -> 45974 | C21: =VLOOKUP(A21,SKILLED!$A:$J,10,0) -> 46060 | D21: cancelled | I21: Hannegan, C. | J21: =VLOOKUP(I21,UNSKILLED!$A:$J,9,0) -> 45958 | K21: =VLOOKUP(I21,UNSKILLED!$A:$J,10,0) -> 46053
A22: Medina, G. | B22: =VLOOKUP(A22,SKILLED!A:I,9,0) -> 45987 | C22: =VLOOKUP(A22,SKILLED!$A:$J,10,0) -> 46062 | I22: Miller, D. | J22: =VLOOKUP(I22,UNSKILLED!$A:$J,9,0) -> 45967 | K22: =VLOOKUP(I22,UNSKILLED!$A:$J,10,0) -> 46053
A23: Alcaraz, A. | B23: =VLOOKUP(A23,SKILLED!A:I,9,0) -> 46031 | C23: =VLOOKUP(A23,SKILLED!$A:$J,10,0) -> 46062 | I23: Kudlemyer, C. | J23: =VLOOKUP(I23,UNSKILLED!$A:$J,9,0) -> 45990 | K23: =VLOOKUP(I23,UNSKILLED!$A:$J,10,0) -> 46053
A24: Jones, S. | B24: =VLOOKUP(A24,SKILLED!A:I,9,0) -> 46000 | C24: =VLOOKUP(A24,SKILLED!$A:$J,10,0) -> 46063 | I24: Neri, M. | J24: =VLOOKUP(I24,UNSKILLED!$A:$J,9,0) -> 45992 | K24: =VLOOKUP(I24,UNSKILLED!$A:$J,10,0) -> 46053
A25: Sanchez, G. | B25: =VLOOKUP(A25,SKILLED!A:I,9,0) -> 45978 | C25: =VLOOKUP(A25,SKILLED!$A:$J,10,0) -> 46072 | I25: Glancy, L. | J25: =VLOOKUP(I25,UNSKILLED!$A:$J,9,0) -> 46013 | K25: =VLOOKUP(I25,UNSKILLED!$A:$J,10,0) -> 46053
A26: Chaaban, R. | B26: =VLOOKUP(A26,SKILLED!A:I,9,0) -> 46023 | C26: =VLOOKUP(A26,SKILLED!$A:$J,10,0) -> 46073 | I26: Verdugo, D. | J26: =VLOOKUP(I26,UNSKILLED!$A:$J,9,0) -> 46029 | K26: =VLOOKUP(I26,UNSKILLED!$A:$J,10,0) -> 46054 | L26: extended, pending updated auth
A27: Wright, L. | B27: =VLOOKUP(A27,SKILLED!A:I,9,0) -> 46000 | C27: =VLOOKUP(A27,SKILLED!$A:$J,10,0) -> 46079 | I27: Gashimov, K. | J27: =VLOOKUP(I27,UNSKILLED!$A:$J,9,0) -> 45924 | K27: =VLOOKUP(I27,UNSKILLED!$A:$J,10,0) -> 46054
A28: Huynh, J. | B28: =VLOOKUP(A28,SKILLED!A:I,9,0) -> 45974 | C28: =VLOOKUP(A28,SKILLED!$A:$J,10,0) -> 46080 | I28: Campbell, C. | J28: =VLOOKUP(I28,UNSKILLED!$A:$J,9,0) -> 46029 | K28: =VLOOKUP(I28,UNSKILLED!$A:$J,10,0) -> 46054
A29: Mendez, M. | B29: =VLOOKUP(A29,SKILLED!A:I,9,0) -> 45974 | C29: =VLOOKUP(A29,SKILLED!$A:$J,10,0) -> 46080 | I29: Boston, J. | J29: =VLOOKUP(I29,UNSKILLED!$A:$J,9,0) -> 45898 | K29: =VLOOKUP(I29,UNSKILLED!$A:$J,10,0) -> 46056
A30: Gallegos, M. | B30: =VLOOKUP(A30,SKILLED!A:I,9,0) -> 45978 | C30: =VLOOKUP(A30,SKILLED!$A:$J,10,0) -> 46081 | I30: Arnold, M. | J30: =VLOOKUP(I30,UNSKILLED!$A:$J,9,0) -> 45980 | K30: =VLOOKUP(I30,UNSKILLED!$A:$J,10,0) -> 46081
A31: Garcia Chavez, L. | B31: =VLOOKUP(A31,SKILLED!A:I,9,0) -> 45931 | C31: =VLOOKUP(A31,SKILLED!$A:$J,10,0) -> 46081 | I31: Bradbury, F. | J31: =VLOOKUP(I31,UNSKILLED!$A:$J,9,0) -> 46008 | K31: =VLOOKUP(I31,UNSKILLED!$A:$J,10,0) -> 46081 | L31: extended pending auth
A32: Fuentes, A. | B32: =VLOOKUP(A32,SKILLED!A:I,9,0) -> 45918 | C32: =VLOOKUP(A32,SKILLED!$A:$J,10,0) -> 46081 | I32: Kapp, M. | J32: =VLOOKUP(I32,UNSKILLED!$A:$J,9,0) -> 45910 | K32: =VLOOKUP(I32,UNSKILLED!$A:$J,10,0) -> 46081
A33: Rider, L. | B33: =VLOOKUP(A33,SKILLED!A:I,9,0) -> 45898 | C33: =VLOOKUP(A33,SKILLED!$A:$J,10,0) -> 46081 | I33: Kapp, H. | J33: =VLOOKUP(I33,UNSKILLED!$A:$J,9,0) -> 45911 | K33: =VLOOKUP(I33,UNSKILLED!$A:$J,10,0) -> 46081
A34: Sims, S. | B34: =VLOOKUP(A34,SKILLED!A:I,9,0) -> 45897 | C34: =VLOOKUP(A34,SKILLED!$A:$J,10,0) -> 46081 | I34: Werntz, D. | J34: =VLOOKUP(I34,UNSKILLED!$A:$J,9,0) -> 45912 | K34: =VLOOKUP(I34,UNSKILLED!$A:$J,10,0) -> 46081
A35: Fudge, R. | B35: =VLOOKUP(A35,SKILLED!A:I,9,0) -> 45994 | C35: =VLOOKUP(A35,SKILLED!$A:$J,10,0) -> 46083 | I35: Dulina, D. | J35: =VLOOKUP(I35,UNSKILLED!$A:$J,9,0) -> 45919 | K35: =VLOOKUP(I35,UNSKILLED!$A:$J,10,0) -> 46081
A36: Sanchez Y Lara, M. | B36: =VLOOKUP(A36,SKILLED!A:I,9,0) -> 45903 | C36: =VLOOKUP(A36,SKILLED!$A:$J,10,0) -> 46084 | I36: Berend, S. | J36: =VLOOKUP(I36,UNSKILLED!$A:$J,9,0) -> 45925 | K36: =VLOOKUP(I36,UNSKILLED!$A:$J,10,0) -> 46081
A37: Martinez, S. | B37: =VLOOKUP(A37,SKILLED!A:I,9,0) -> 46023 | C37: =VLOOKUP(A37,SKILLED!$A:$J,10,0) -> 46090 | D37: extended, pending updated auth with corrected expiration date | I37: Meyo, A. | J37: =VLOOKUP(I37,UNSKILLED!$A:$J,9,0) -> 45931 | K37: =VLOOKUP(I37,UNSKILLED!$A:$J,10,0) -> 46081
A38: Jimenez, G. | B38: =VLOOKUP(A38,SKILLED!A:I,9,0) -> 45910 | C38: =VLOOKUP(A38,SKILLED!$A:$J,10,0) -> 46091 | I38: Thompson, L. | J38: =VLOOKUP(I38,UNSKILLED!$A:$J,9,0) -> 45931 | K38: =VLOOKUP(I38,UNSKILLED!$A:$J,10,0) -> 46081
A39: Macias, J. | B39: =VLOOKUP(A39,SKILLED!A:I,9,0) -> 45910 | C39: =VLOOKUP(A39,SKILLED!$A:$J,10,0) -> 46091 | I39: Anderman, C. | J39: =VLOOKUP(I39,UNSKILLED!$A:$J,9,0) -> 45933 | K39: =VLOOKUP(I39,UNSKILLED!$A:$J,10,0) -> 46081
A40: Appell, L. | B40: =VLOOKUP(A40,SKILLED!A:I,9,0) -> 46005 | C40: =VLOOKUP(A40,SKILLED!$A:$J,10,0) -> 46095 | I40: Cork, J. | J40: =VLOOKUP(I40,UNSKILLED!$A:$J,9,0) -> 45933 | K40: =VLOOKUP(I40,UNSKILLED!$A:$J,10,0) -> 46081
...

Sheet Sheet3

Sheet Holidays
A1: FHCP EMPLOYEES | B1: email | C1: 619-515-2445 ext.
A2: Claire Wedemier | B2: clairew@fhcsd.org | C2: 7003
A3: Gwen Banes | B3: gwendolynb@fhcsd.org | C3: 7006
A4: Maribel Estrada | B4: maribele@fhcsd.org | C4: 7017
A5: Mercy Crelly | B5: mercyc@fhcsd.org | C5: 5940
A6: Andrey Pentzakoff | B6: andreyp@fhcsd.org | C6: 7011
A7: Dalia Razo | B7: daliara@fhcsd.org | C7: 7046
A8: Leah Cabrera | B8: leahc@fhcsd.org | C8: 8061
A9: Colleen Bosse | B9: colleenb@fhcsd.org | C9: 619-838-5553
A10: Edward Whalen | B10: edwardwh@fhcsd.org
A11: Irina Kops | B11: irinak@fhcsd.org
A12: Jillian Hanes | B12: jillianruthh@fhcsd.org
A13: Esther Chacon | B13: estherc@fhcsd.org | C13: 619-952-4089
A14: Tia Huggins | B14: lindah@fhcsd.org
A15: Silvia Valdez | B15: silvia@fhcsd.org | C15: 619-502-2007
A16: Sandra Coronel | B16: Sandracor@fhcsd.org
A18: FHCP HOLIDAYS
A19: Memorial Day | B19: July 4th | C19: Labor Day
A20: Thanksgiving Day | B20: Christmas Day
A21: A day after thanksgiving | B21: New Year's Day
A26: Date | B26: Day of Week | C26: Holiday Name | D26: HC | E26: HC
A27: 45292 | B27: Wednesday | C27: New Year’s Day | D27: Denise | E27: Edward | F27: Delilah | G27: Juan Macias
A28: 45803 | B28: Monday | C28: Memorial Day | D28: Denise | E28: Edward | F28: Delilah | G28: Juan Macias
A29: 45477 | B29: Friday | C29: Independence Day | D29: Denise | E29: Edward | F29: Delilah | G29: Juan Macias
A30: 45901 | B30: Monday | C30: Labor Day | D30: Denise | E30: Edward | F30: Delilah | G30: Juan Macias
A31: 45988 | B31: Thursday | C31: Thanksgiving Day | D31: Denise | E31: Edward | F31: Delilah | G31: Juan Macias
A32: 45989 | B32: Friday | C32: A Day after Thanksgiving
A33: 45651 | B33: Thursday | C33: Christmas Day | D33: Denise | E33: Edward | F33: Delilah | G33: Juan Macias

Sheet FHC Active Employees
A1: C.N.A./PCA | B1: LVN | C1: RN | D1: North County RN
A2: Adriana Chavez | B2: Akilah Hudson | C2: Adam Miller | D2: Blair Dietrich
A3: Andres Gomez | B3: Anne Lawrence | C3: Amanda Meyers | D3: Cristina Malinis
A4: Belem Brown | B4: Danilo Nagal | C4: Benny Grepo | D4: Frances Raquino
A5: Keah Gomez | B5: Don McCluster | C5: Colleen Rose | D5: Irene Grepo
A6: Bethzaida Kiah | B6: Ejigayehu Wakjira | C6: Fatemeh Veisch | D6: Joshua Hahn
A7: Claudia Fronda | B7: Eric Estes | C7: Heidi Wester | D7: Kenneth Sierleja (Deployed)
A8: Daisy Famobuwa | B8: Jayvee Varela | C8: Jervia Fickens | D8: Stacy Munro
A9: Daniel Chavez | B9: Margo Porter | C9: Josephine Marshall | D9: Tasha Carey
A10: Diana Noriega Martinez | B10: Nadhii Bachie | C10: Kathleen Bautista | D10: Sandra Oswald
A11: Bibiana Mendoza | B11: Sche'kinah Ortiz (Indefinite Leave) | C11: Malcolm Linton | D11: Athena Dahlin
A12: Ekjot Atwal | B12: Rochelle Goose | C12: Mary Brown | D12: Kristina Zuanich
... A14: Eliseo Mancilla | B14: Cynthia Resendiz | C14: Michel Fonte | D14: Sierra Brown
A15: Ethna Bela | C15: Michelle Sanantonio | D15: Amanda Stanford
A16: George Cachu | C16: Monique Ramos | D16: Douglas Taylor
A17: Guadalupe Martinez | C17: Priscilla Castro Blake
A18: Hadassa Yusuf | C18: Ray Clarence Reyes
A19: Irma Briseno | C19: Elsey Hoopi
A20: Jasmin Jauregui | C20: Renee Ramos
A21: Margarita Garcia Mata | C21: Nicole Sahagun
A22: Marimar Valdez Camacho | C22: Andrea Jacome
A23: Maryam Zarabi | C23: Kristina Punsalan
A24: Mordecai Yusuf | C24: Byron Bandonell
A25: Patricia Flores | C25: Felsie Joy Cortes
A26: Perla Carrera | C26: Anna Tiria
A27: Roya Tahiry | C27: Gabriela Musgrave
A28: Salamatu Musa
A29: Samantha Rodriguez
A30: Sophia Zouvas
A31: Susan Rubalcava
A32: Trina Tahiry
A33: Vincent Sanantonio
A34: Miriam Garcia Estrada
A35: Tristan Ortega
A36: Tamir Lucas
A37: Beatrice Amoah
A38: Rifqa Anglo
A39: Parwin Shirzad
... A63: Active / Visiting patients

Sheet Sheet10
A1: Mercedes Salazar
A4: 37384

Sheet Employees
A4: C.N.A./PCA | B4: LVN | C4: RN | D4: North County
A5: Perla C. | B5: Danilo N. | C5: Heidi W. | D5: Kenneth S.
A6: Diana M. | B6: Don M. | C6: Michael H. | D6: Tasha C.
A7: Andres G. | B7: June M. | C7: Patrick K. | D7: Brandon L.
A8: Samantha R. | B8: Sche'kinah O. | C8: Renee R. | D8: Stacy M.
A9: Norka M. | B9: Natasha S. | C9: Monique R. | D9: Joshua H.
A10: Vincent S. | B10: Lakisha L. | C10: Michelle S. | D10: Fernanda C.
A11: Joy C. | B11: Margo P. | C11: Malcolm L. | D11: Lakeisha G.
A12: Trina T. | B12: Eric E. | C12: Jervia F. | D12: Irene G.
A13: Roya T. | B13: Margo P. | C13: Mary B. | D13: Cristina M.
A14: Hadassa Y. | B14: Karla G. | C14: Jeanne B.* | D14: Daniella G.
A15: Patricia F. | B15: Jayvee J. | C15: Kathleen B. | D15: Frances R.
A16: Marilyn G. | B16: Carla C. | C16: Blair D. | D16: Stacy M.
A17: Eliseo M. | B17: Nadhii B. | C17: Kristina Z.
A18: Maleah H. | B18: Anne (Noel) L. | C18: Priscilla C.
A19: Jessica B. | B19: Nadhii B. | C19: Josephine M.
A20: Guadalupe M. | C20: Adam M.
A21: Adayilo Y. | C21: Luis M.
A22: Mynerva R. | C22: Ray R.
A23: Ethna B. | C23: Amanda M.
A24: Lara R. | C24: Patel R.
A25: Giselle H. | C25: Jamell B.
A26: Fatima T. | C26: Byron B.
A27: Ekjot A. | C27: Mariko S.
A28: Maya E. | C28: Alyssa G.
A29: Eknoor A. | C29: Ejigayehu (Jijee)
A30: Mirtha S. | C30: Brigette S.
A31: Jacqueline L. | C31: Michel F.
A32: Sandra M.
A33: Chloe A.
A34: Muniba D.
A35: Abigail A.
A36: Susan R.
A37: Daisy F.
A38: Fatuma S.

Sheet Sheet1
A1: Full Name | B1: Hiring Source | C1: Most Recent Hire
A2: Monique Ramos | B2: Brightstar | C2: 44254
A3: Renee Ramos | B3: Brightstar | C3: 44285
A4: Eric Estes | B4: Brightstar | C4: 44442
A5: Michelle Sanantonio | B5: Brightstar | C5: 44449
A6: Margo Porter | B6: Brightstar | C6: 44484
A7: Yolanda Tolliver | B7: Brightstar | C7: 44485
A8: Perla Carrera | B8: Brightstar | C8: 44527
A9: Patricia Stanford | B9: Brightstar | C9: 44554
A10: Patricia Flores | B10: Brightstar | C10: 44562
A11: Emily Jimenez | B11: Brightstar | C11: 44651
A12: Damascene Tumaine | B12: Brightstar | C12: 44718
A13: Malcolm Linton | B13: Brightstar | C13: 44841
... A26: Vincent Sanantonio | B26: Brightstar | C26: 45208

Sheet Sheet2

Sheet Sheet4
A1: C.N.A./PCA | B1: LVN | C1: RN | D1: North County RN
A2: Abigail Adrianse | B2: Akilah Hudson | C2: Adam Miller | D2: Blair Dietrich
A3: Adayilo (Gift) Yusuf | B3: Anne Lawrence | C3: Amanda Meyers | D3: Byron Bandonell
A4: Andres Gomez | B4: Danilo Nagal | C4: Benny Grepo | D4: Cristina Malinis
A5: Belem Brown | B5: Don McCluster | C5: Brian Melgar | D5: Daniela Gonzalez
A6: Bethzaida Kiah | B6: Ejigayehu Wakjira | C6: Colleen Rose | D6: Fernanda Carvalho
A7: Daisy Famobuwa | B7: Eric Estes | C7: Cristina Malinis | D7: Frances Raquino
A8: Daniel Chavez | B8: Jayvee Varela | C8: Daniela Gonzalez | D8: Irene Grepo
A9: Diana Noriega Martinez | B9: June Medina | C9: Frances Raquino | D9: Joshua Hahn
A10: Ekjot Atwal | B10: Margo Porter | C10: Heidi Wester | D10: Kenneth Sierleja
A11: Eknoor Atwal | B11: Nadhii Bachie | C11: James Snyder | D11: Stacy Munro
A12: Eliseo Mancilla | B12: Sche'kinah Ortiz | C12: Jervia Fickens | D12: Tasha Carey
A13: Ethna Bela | C13: Josephine Marshall
A14: Fatuma Shulungu | C14: Joshua Hahn
A15: Felicia Cain | C15: Kathleen Bautista
A16: George Cachu | C16: Luis Martinez
A17: Giselle Herrera | C17: Malcolm Linton
A18: Gladimir Dumorne | C18: Mariko Sato
A19: Guadalupe Martinez | C19: Mary Brown
A20: Hadassa Yusuf | C20: Michael Horton
A21: Jasmin Jauregui | C21: Michel Fonte
A22: Keah Gomez | C22: Michelle Sanantonio
A23: Leticia Reyes | C23: Monique Ramos
A24: Margarita Mata | C24: Priscilla Castro Blake
... A26: Marilyn Gabriana | C26: Renee Ramos
A27: Marimar Valdez camacho
A28: Maryam Zarabi
A29: Mordecai Yusuf
A30: Mynerva Ramirez Trebil
A31: Patricia Flores
A32: Patricia Stanford
A33: Perla Carrera
A34: Roya Tahiry
A35: Salamatu Musa
A36: Samantha Rodriguez
A37: Sandra McGowan
A38: Susan Rubalcava
... A65: Kristina Zuanich

Sheet Sheet5
A1: HOME HEALTH/SKILLED Participant's First and Last Name | B1: Case Managers
A2: Alonzo, D. | B2: Mercy
A3: Araujo, D. | B3: Galia
A4: Audia, A. | B4: Galia
A5: Bahena, J. | B5: Maribel
A6: Barajas Barragan, A. | B6: Galia
A7: Brae, A. | B7: Galia
A8: Calderon, E. | B8: Galia
A9: Calderon, G. | B9: Aaron
A10: Campbell, C | B10: Nehita
A11: Clark, D. | B11: Nehita
A12: Corrales, G. | B12: Aaron
... A92: Zuniga Sandoval, V. | B92: Aaron

Sheet Sheet6
A1: Mercedes S. | B1: Time | C1: CG
A2: 5/8/2025 (Thurs) | B2: 5pm-5am | C2: Adriana
A4: 5/9/2025 (Friday) | B4: 5am - 7am | C4: Trina
B5: 5pm-5am | C5: Emily
A7: 5/10/2025 (Saturday) | B7: 5am-7am | C7: Trina
B8: 7am-7pm | C8: Claudia
B9: 7pm-7am | C9: Samantha
A11: 5/11/2025 (Sunday) | B11: 7am-7pm | C11: Claudia
B12: 7pm-7am | C12: Samantha
A14: 5/12/2025 (Monday) | B14: 5pm - 5am | C14: Adriana
B15: 5am-7am | C15: Trina
A17: 5/13/2025(Tuesday) | B17: 5pm - 5am | C17: Adriana
B18: 5am-7am | C18: Trina

Sheet Sheet8
A1: Gilberto Medina
A2: Nathaniel Gardner
A3: Genaro Calderon
A4: Guillermo Corrales
A5: Annette Tucker
A6: Steven Berend
A7: Alma Martinez
A8: Dolores Medrano
A9: Moreno Cardneas
A10: Rosemary Raney
A11: Jessie Suit
A12: Eana Tsehaynesh
... A35: Phillip Bishay

Sheet Sheet9
A2: Participant (ppt) | B2: Inclusive dates of coverage needed | D2: Assigned Nurse | E2: Notes
A3: Denise V. | B3: Mon, Tues, Th, & Fri | C3: June 02 until June 20, 2025 | D3: Fatemeh
A4: Edgar L. | B4: Thurs only | C4: June 05, 12, & 19 | D4: Fatemeh | E4: EXP: 5/26/2025
A5: Daniel A. | B5: Mon & Fri only | C5: June 2, 6, 9, 13, 16, & 20 | D5: Eric | E5: EXP: 4/27/2025 (Ongoing)
A6: Celia M. | B6: Monday thru Friday | C6: June 02 until June 20, 2025 | D6: Margo | E6: EXP: 5/27/2025 (Ongoing)
A7: Roberto R. | B7: Wed only | C7: June 04, 11, & 18 | D7: Margo
A8: Jefferey R. | B8: MWF | C8: June 02 until June 20, 2025 | D8: Margo
A9: Maria D. | B9: Thurs only | C9: June 05, 12, & 19 | D9: Michelle S. | E9: follow up on June 1st to confirm her availability
